<?xml version="1.0" ?>
<robot name="brazo_omni" xmlns:xacro="http://www.ros.org/wiki/xacro">

<xacro:include filename="$(find brazo_omni_description)/urdf/materials.xacro" />
<xacro:include filename="$(find brazo_omni_description)/urdf/brazo_omni.trans" />
<xacro:include filename="$(find brazo_omni_description)/urdf/brazo_omni.gazebo" />
<link name="base_link">
  <inertial>
    <origin xyz="-0.005540193790928124 7.370553273120713e-18 0.00724588623657782" rpy="0 0 0"/>
    <mass value="0.6054102338350126"/>
    <inertia ixx="0.000419" iyy="0.000276" izz="0.00063" ixy="-0.0" iyz="-0.0" ixz="-8e-06"/>
  </inertial>
  <visual>
    <origin xyz="0 0 0" rpy="0 0 0"/>
    <geometry>
      <mesh filename="package://brazo_omni_description/meshes/base_link.stl" scale="0.001 0.001 0.001"/>
    </geometry>
    <material name="silver"/>
  </visual>
  <collision>
    <origin xyz="0 0 0" rpy="0 0 0"/>
    <geometry>
      <mesh filename="package://brazo_omni_description/meshes/base_link.stl" scale="0.001 0.001 0.001"/>
    </geometry>
  </collision>
</link>

<link name="l1_1">
  <inertial>
    <origin xyz="1.5924509824096877e-10 -0.024999988944218354 0.06944981476509293" rpy="0 0 0"/>
    <mass value="0.7212107061266948"/>
    <inertia ixx="0.00243" iyy="0.002364" izz="0.000137" ixy="-0.0" iyz="-0.0" ixz="-0.0"/>
  </inertial>
  <visual>
    <origin xyz="-0.0 -0.025 -0.025" rpy="0 0 0"/>
    <geometry>
      <mesh filename="package://brazo_omni_description/meshes/l1_1.stl" scale="0.001 0.001 0.001"/>
    </geometry>
    <material name="silver"/>
  </visual>
  <collision>
    <origin xyz="-0.0 -0.025 -0.025" rpy="0 0 0"/>
    <geometry>
      <mesh filename="package://brazo_omni_description/meshes/l1_1.stl" scale="0.001 0.001 0.001"/>
    </geometry>
  </collision>
</link>

<link name="l2_1">
  <inertial>
    <origin xyz="1.592451013345226e-10 -0.024999988944218367 0.06944981476509296" rpy="0 0 0"/>
    <mass value="0.7212107061266951"/>
    <inertia ixx="0.00243" iyy="0.002364" izz="0.000137" ixy="-0.0" iyz="-0.0" ixz="-0.0"/>
  </inertial>
  <visual>
    <origin xyz="-0.0 -0.025 -0.175" rpy="0 0 0"/>
    <geometry>
      <mesh filename="package://brazo_omni_description/meshes/l2_1.stl" scale="0.001 0.001 0.001"/>
    </geometry>
    <material name="silver"/>
  </visual>
  <collision>
    <origin xyz="-0.0 -0.025 -0.175" rpy="0 0 0"/>
    <geometry>
      <mesh filename="package://brazo_omni_description/meshes/l2_1.stl" scale="0.001 0.001 0.001"/>
    </geometry>
  </collision>
</link>

<link name="l3_1">
  <inertial>
    <origin xyz="1.5924509514741469e-10 -0.024999988944218378 0.06944981476509277" rpy="0 0 0"/>
    <mass value="0.7212107061266956"/>
    <inertia ixx="0.00243" iyy="0.002364" izz="0.000137" ixy="-0.0" iyz="-0.0" ixz="-0.0"/>
  </inertial>
  <visual>
    <origin xyz="-0.0 -0.025 -0.325" rpy="0 0 0"/>
    <geometry>
      <mesh filename="package://brazo_omni_description/meshes/l3_1.stl" scale="0.001 0.001 0.001"/>
    </geometry>
    <material name="silver"/>
  </visual>
  <collision>
    <origin xyz="-0.0 -0.025 -0.325" rpy="0 0 0"/>
    <geometry>
      <mesh filename="package://brazo_omni_description/meshes/l3_1.stl" scale="0.001 0.001 0.001"/>
    </geometry>
  </collision>
</link>

<link name="end_effector_1" concave="yes">
  <inertial>
    <origin xyz="0.0018769943609454375 -0.02500000000000892 0.007657259532162564" rpy="0 0 0"/>
    <mass value="0.2670228230734712"/>
    <inertia ixx="0.000121" iyy="0.000104" izz="5e-05" ixy="-0.0" iyz="0.0" ixz="-1.8e-05"/>
  </inertial>
  <visual>
    <origin xyz="-0.0 -0.025 -0.475" rpy="0 0 0"/>
    <geometry>
      <mesh filename="package://brazo_omni_description/meshes/end_effector_1.stl" scale="0.001 0.001 0.001"/>
    </geometry>
    <material name="silver"/>
  </visual>
  <collision >
    <origin xyz="-0.0 -0.025 -0.475" rpy="0 0 0"/>
    <geometry>
      <mesh filename="package://brazo_omni_description/meshes/end_effector_1.stl" scale="0.001 0.001 0.001"/>
    </geometry>
  </collision>
</link>

<joint name="l1_to_base_link" type="revolute">
  <origin xyz="0.0 0.025 0.025" rpy="0 0 0"/>
  <parent link="base_link"/>
  <child link="l1_1"/>
  <axis xyz="0.0 1.0 0.0"/>
  <limit upper="1.570796" lower="-1.570796" effort="100" velocity="100"/>
</joint>

<joint name="l2_to_l1" type="revolute">
  <origin xyz="0.0 0.0 0.15" rpy="0 0 0"/>
  <parent link="l1_1"/>
  <child link="l2_1"/>
  <axis xyz="0.0 1.0 0.0"/>
  <limit upper="1.919862" lower="-1.919862" effort="100" velocity="100"/>
</joint>

<joint name="l3_to_l2" type="revolute">
  <origin xyz="0.0 0.0 0.15" rpy="0 0 0"/>
  <parent link="l2_1"/>
  <child link="l3_1"/>
  <axis xyz="0.0 1.0 0.0"/>
  <limit upper="1.919862" lower="-1.919862" effort="100" velocity="100"/>
</joint>

<joint name="end_effector_to_l3" type="revolute">
  <origin xyz="0.0 0.0 0.15" rpy="0 0 0"/>
  <parent link="l3_1"/>
  <child link="end_effector_1"/>
  <axis xyz="0.0 1.0 0.0"/>
  <limit upper="2.094395" lower="-2.094395" effort="100" velocity="100"/>
</joint>

</robot>
