<?xml version="1.0"?>

<robot xmlns:xacro="http://ros.org/wiki/xacro"
  name="katana_300_6m180">

  <xacro:include filename="$(find katana_description)/urdf/transmissions.urdf.xacro"/>
  <xacro:include filename="$(find katana_description)/urdf/gazebo.urdf.xacro"/>

  <property name="M_PI" value="3.1415926535897931" />

  <!-- all values from the katana manual -->
  <property name="base_height" value="0.2015" />
  <property name="link2_length" value="0.19" />
  <property name="link3_length" value="0.139" />
  <property name="link4_length" value="0.1523" />
  <property name="link5_length" value="0.1505" />
  
  <!-- Base Link -->
  <link name="katana_base_link">
    <visual>
      <origin xyz="0 0 0" rpy="0 0 0" />
      <geometry>
        <mesh filename="package://katana/katana/katana_base_link.stl"/>
      </geometry>
      <material name="grey">
        <color rgba="0.8 0.8 0.8 1"/>
      </material>
    </visual>
    <collision>
      <origin xyz="0 0 0" rpy="0 0 0" />
      <geometry>
        <mesh filename="package://katana/katana/katana_base_link.stl"/>
      </geometry>
    </collision>
    <inertial>
      <mass value="1.4047990875" />
      <origin xyz="-0.000327 0.000908 0.058457"/>
      <inertia ixx="0.003000703" ixy="0.000000864" ixz="-0.000011312" 
        iyy="0.002974822" iyz="0.000036294" 
        izz="0.001434739" />
    </inertial>
  </link>

  <!-- Joint 1 -->
  <joint name="katana_motor1_pan_joint" type="revolute">
    <parent link="katana_base_link"/>
    <child link="katana_motor1_pan_link" />
    <origin xyz="0 0 0.2015" rpy="0 0 0"/>
    <axis xyz="0 0 1"/>
    <limit effort="1.5" lower="-3.025528" upper="2.891097" velocity="2.208932"/>
  </joint>

  <!-- Link motor1_pan -->
  <link name="katana_motor1_pan_link">
    <visual>
      <origin xyz="0 0 -0.2015" rpy="0 0 0" />
      <geometry>
        <mesh filename="package://katana/katana/katana_motor1_pan_link.stl"/>
      </geometry>
      <material name="grey" />
    </visual>
    <collision>
      <origin xyz="0 0 -0.2015" rpy="0 0 0" />
      <geometry>
        <mesh filename="package://katana/katana/katana_motor1_pan_link.stl"/>
      </geometry>
    </collision>
    <inertial>
      <mass value="0.74793301875" />
      <origin xyz="-0.000410 -0.001285 -0.016774" />
      <inertia ixx="0.001737241" ixy="0.000000421" ixz="0.000000650" 
        iyy="0.000998782" iyz="0.000016114" 
        izz="0.001349170" />    
    </inertial>
  </link>

  <!-- Joint 2 -->
  <joint name="katana_motor2_lift_joint" type="revolute">
    <parent link="katana_motor1_pan_link" />
    <child link="katana_motor2_lift_link" />
    <origin xyz="0 0 0" rpy="1.5708 0 0"/>
    <axis xyz="0 0 1"/>
    <limit effort="0.6" lower="-0.135228" upper="2.168572"  velocity="1.190799"/>
  </joint>

  <!-- Link motor2_lift -->
  <link name="katana_motor2_lift_link">
    <visual>
      <origin rpy="$-1.5708 0 0" xyz="0 0 0"/>
      <geometry>
        <mesh filename="package://katana/katana/katana_motor2_lift_link.stl"/>
      </geometry>
      <material name="grey" />
    </visual>
    <collision>
      <origin rpy="-1.5708 0 0" xyz="0 0 0"/>
      <geometry>
        <mesh filename="package://katana/katana/katana_motor2_lift_link.stl"/>
      </geometry>
    </collision>
    <inertial>
      <mass value="0.80174941875" />
      <origin xyz="0.092420 0.005283 0.000172"/>
      <inertia ixx="0.000478252" ixy="0.000081166" ixz="0.000003961" 
        iyy="0.004314636" iyz="0.000000332" 
        izz="0.004625444" />
    </inertial>
  </link>

  <!-- Joint 3 -->
  <joint name="katana_motor3_lift_joint" type="revolute">
    <parent link="katana_motor2_lift_link" />
    <child  link="katana_motor3_lift_link" />
    <origin xyz="0.19 0 0" rpy="0 0 0"/>
    <axis xyz="0 1 0"/>
    <limit effort="0.25" lower="-2.221804" upper="2.054223"  velocity="1.190799"/>
  </joint>

  <!-- Link motor3_lift -->
  <link name="katana_motor3_lift_link">
    <visual>
      <origin rpy="-1.5708 0 0" xyz="0 0 0"/>
      <geometry>
        <mesh filename="package://katana/katana/katana_motor3_lift_link.stl"/>
      </geometry>
      <material name="grey" />
    </visual>
    <collision>
      <origin rpy="$-1.5708 0 0" xyz="0 0 0"/>
      <geometry>
        <mesh filename="package://katana/katana/katana_motor3_lift_link.stl"/>
      </geometry>
    </collision>
    <inertial>
      <mass value="0.79241664375" />
      <origin xyz="0.058036 0.008963 -0.000187"/>
      <inertia ixx="0.001156089" ixy="0.000112877" ixz="-0.000004398" 
        iyy="0.002305646" iyz="-0.000000036" 
        izz="0.003128648" />
    </inertial>
  </link>

  <!-- Joint 4 -->
  <joint name="katana_motor4_lift_joint" type="revolute">
    <parent link="katana_motor3_lift_link" />
    <child  link="katana_motor4_lift_link" />
    <origin rpy="1.5708 0 0" xyz="0.139 0 0"/>
    <axis xyz="0 1 0"/>
    <limit effort="0.1" lower="-2.033309" upper="1.876133"  velocity="2.208932"/>
  </joint>

  <!-- Link motor4_lift -->
  <link name="katana_motor4_lift_link">
    <visual>
      <origin rpy="1.5708 0 0" xyz="0 0 0"/>
      <geometry>
        <mesh filename="package://katana/katana/katana_motor4_lift_link.stl"/>
      </geometry>
      <material name="grey" />
    </visual>
    <collision>
      <origin rpy="1.5708 0 0" xyz="0 0 0"/>
      <geometry>
        <mesh filename="package://katana/katana/katana_motor4_lift_link.stl"/>
      </geometry>
    </collision>
    <inertial>
      <mass value="0.69149323125" />
      <origin xyz="0.050401 0.005807 0.000000"/>
      <inertia ixx="0.000765999" ixy="0.000045260" ixz="-0.000001210" 
        iyy="0.001504115" iyz="0.000000147" 
        izz="0.001887277" />
    </inertial>
  </link>

  <!-- Joint 5 -->
  <joint name="katana_motor5_wrist_roll_joint" type="revolute">
    <parent link="katana_motor4_lift_link" />
    <child  link="katana_motor5_wrist_roll_link" />
    <origin rpy="1.5708 0 -1.5708" xyz="0.1523 0 0"/>
    <axis xyz="0 0 1"/>
    <limit effort="0.01" lower="-2.993240" upper="2.870985"  velocity="2.208932"/>
  </joint>

  <!-- Link motor5_wrist_roll -->
  <link name="katana_motor5_wrist_roll_link">
    <visual>
      <origin rpy="0 3.14159 0" xyz="0 0 0"/>
      <geometry>
        <mesh filename="package://katana/katana/katana_motor5_wrist_roll_link.stl"/>
      </geometry>
      <material name="grey" />
    </visual>
    <collision>
      <origin rpy="0 3.14159 0" xyz="0 0 0"/>
      <geometry>
        <mesh filename="package://katana/katana/katana_motor5_wrist_roll_link.stl"/>
      </geometry>
    </collision>
    <inertial>
      <mass value="0.25622555625" />
      <origin xyz="-0.003140899 0.000013920 0.001680144"/>
      <inertia ixx="0.000120481" ixy="0.000000015" ixz="-0.000001089" 
        iyy="0.000132130" iyz="-0.000000124" 
        izz="0.000093522" />
    </inertial>
  </link>

  <!-- Joint Gripper Fixed -->
  <joint name="katana_gripper_joint" type="fixed">
    <parent link="katana_motor5_wrist_roll_link" />
    <child link="katana_gripper_link" />
    <origin rpy="0 1.5708 0" xyz="0 0 -0.0323"/>
  </joint>

  <!-- Link Gripper -->
  <link name="katana_gripper_link">
    <visual>
      <origin rpy="0 3.14159 0" xyz="0 0 0"/>
      <geometry>
        <mesh filename="package://katana/katana/katana_gripper_link.stl"/>
      </geometry>
      <material name="grey" />
    </visual>
    <collision>
      <origin rpy="0 3.14159 0" xyz="0 0 0"/>
      <geometry>
        <mesh filename="package://katana/katana/katana_gripper_link.stl"/>
      </geometry>
    </collision>
    <inertial>
      <mass value="0.0552136183596" />
      <origin xyz="-0.014379 -0.000000 0.000006"/>
      <inertia ixx="0.000011468" ixy="0.000000000" ixz="0.000000007" 
        iyy="0.000013830" iyz="0.000000000" 
        izz="0.000011290" />
    </inertial>
  </link>

  <!-- Joint Dedo Derecho -->
  <joint name="katana_r_finger_joint" type="revolute">
    <parent link="katana_gripper_link" />
    <child  link="katana_r_finger_link" />
    <origin rpy="0 0 0" xyz="0.034 0 0"/>
    <axis xyz="0 0 1"/>
    <limit effort="0.5" lower="-0.44" upper="0.30"  velocity="0.718834"/>
  </joint>

  <!-- Link Dedo Derecho -->
  <link name="katana_r_finger_link">
    <visual>
      <origin rpy="0 3.14159 0" xyz="0 0 0"/>
      <geometry>
        <mesh filename="package://katana/katana/katana_gripper_r_finger.stl"/>
      </geometry>
      <material name="grey" />
    </visual>
    <collision>
      <origin rpy="0 0 0.610865" xyz="0.025 0.025 0"/>
      <geometry>
        <box size="0.05 0.005 0.02"/>
      </geometry>
    </collision>
    <collision>
      <origin rpy="0 0 -0.523599" xyz="0.06 0.035 0"/>
      <geometry>
        <box size="0.02 0.005 0.02"/>
      </geometry>
    </collision>
    <inertial>
      <mass value="0.0251722230462" />
      <origin xyz="-0.032182 0.025167 -0.001603"/>
      <inertia ixx="0.000005990" ixy="0.000008473" ixz="0.000001448" 
        iyy="0.000019757" iyz="-0.000000996" 
        izz="0.000023588" />        
    </inertial>
  </link>

  <!-- Joint Dedo Izquierdo -->
  <joint name="katana_l_finger_joint" type="revolute">
    <parent link="katana_gripper_link" />
    <child  link="katana_l_finger_link" />
    <origin rpy="3.14159 0 0" xyz="0.034 0 0"/>
    <axis xyz="0 0 1"/>
    <limit effort="0.5" lower="-0.44" upper="0.30"  velocity="0.718834"/>
  </joint>

  <!-- Link Dedo Izquierdo -->
  <link name="katana_l_finger_link">
    <visual>
      <origin rpy="0 3.14159 0" xyz="0 0 0"/>
      <geometry>
        <mesh filename="package://katana/katana/katana_gripper_l_finger.stl"/>
      </geometry>
      <material name="grey" />
    </visual>
    <collision>
      <origin rpy="0 0 0.610865" xyz="0.025 0.025 0"/>
      <geometry>
        <box size="0.05 0.005 0.02"/>
      </geometry>
    </collision>
    <collision>
      <origin rpy="0 0 -0.523599" xyz="0.06 0.035 0"/>
      <geometry>
        <box size="0.02 0.005 0.02"/>
      </geometry>
    </collision>
    <inertial>
      <mass value="0.0251722230462" />
      <origin xyz="-0.032182 0.025167 -0.001603"/>
      <inertia ixx="0.000005990" ixy="0.000008473" ixz="0.000001448" 
        iyy="0.000019757" iyz="-0.000000996" 
        izz="0.000023588" />        
    </inertial>
  </link>


  <!-- Joint Frame Herramienta Gripper -->
  <joint name="katana_gripper_tool_frame_joint" type="fixed">
    <parent link="katana_motor5_wrist_roll_link"/>
    <child link="katana_gripper_tool_frame" />
    <origin xyz="0 0 -0.1505" rpy="0 1.5708 0"/>
  </joint>

  <!-- Link Frame Herramienta Gripper -->
  <link name="katana_gripper_tool_frame">
    <!-- Este es el sistema de coordenadas de la herramienta (posición utilizada en IK, etc., relativa al frame base); no hay una parte del brazo real adjunta a este enlace -->
  </link> 

  <!-- Joint Frame Base -->
  <joint name="katana_base_frame_joint" type="fixed">
    <parent link="katana_base_link"/>
    <child link="katana_base_frame" />
    <origin xyz="0 0 0.2015" rpy="0 0 0"/>
  </joint>

  <!-- Link Frame Base -->
  <link name="katana_base_frame">
    <!-- Este es el sistema de coordenadas de referencia del brazo (la cinemática KNI está especificada en este frame); no hay una parte del brazo real adjunta a este enlace -->
  </link> 

</robot>
