<?xml version="1.0" ?>
<robot name="brazo_omni_v2" xmlns:xacro="http://www.ros.org/wiki/xacro">

<xacro:include filename="$(find brazo_omni_v2_description)/urdf/materials.xacro" />
<xacro:include filename="$(find brazo_omni_v2_description)/urdf/brazo_omni_v2.trans" />
<xacro:include filename="$(find brazo_omni_v2_description)/urdf/brazo_omni_v2.gazebo" />
<link name="base_link">
  <inertial>
    <origin xyz="-0.005540193790928124 7.370553273120713e-18 0.00724588623657782" rpy="0 0 0"/>
    <mass value="0.6054102338350126"/>
    <inertia ixx="0.000419" iyy="0.000276" izz="0.00063" ixy="-0.0" iyz="-0.0" ixz="-8e-06"/>
  </inertial>
  <visual>
    <origin xyz="0 0 0" rpy="0 0 0"/>
    <geometry>
      <mesh filename="package://brazo_omni_v2_description/meshes/base_link.stl" scale="0.001 0.001 0.001"/>
    </geometry>
    <material name="silver"/>
  </visual>
  <collision>
    <origin xyz="0 0 0" rpy="0 0 0"/>
    <geometry>
      <mesh filename="package://brazo_omni_v2_description/meshes/base_link.stl" scale="0.001 0.001 0.001"/>
    </geometry>
  </collision>
</link>

<link name="l1_1">
  <inertial>
    <origin xyz="1.5924509824096877e-10 -0.024999988944218354 0.06944981476509293" rpy="0 0 0"/>
    <mass value="0.7212107061266948"/>
    <inertia ixx="0.00243" iyy="0.002364" izz="0.000137" ixy="-0.0" iyz="-0.0" ixz="-0.0"/>
  </inertial>
  <visual>
    <origin xyz="-0.0 -0.025 -0.025" rpy="0 0 0"/>
    <geometry>
      <mesh filename="package://brazo_omni_v2_description/meshes/l1_1.stl" scale="0.001 0.001 0.001"/>
    </geometry>
    <material name="silver"/>
  </visual>
  <collision>
    <origin xyz="-0.0 -0.025 -0.025" rpy="0 0 0"/>
    <geometry>
      <mesh filename="package://brazo_omni_v2_description/meshes/l1_1.stl" scale="0.001 0.001 0.001"/>
    </geometry>
  </collision>
</link>

<link name="l2_1">
  <inertial>
    <origin xyz="1.592451013345226e-10 -0.024999988944218367 0.06944981476509296" rpy="0 0 0"/>
    <mass value="0.7212107061266951"/>
    <inertia ixx="0.00243" iyy="0.002364" izz="0.000137" ixy="-0.0" iyz="-0.0" ixz="-0.0"/>
  </inertial>
  <visual>
    <origin xyz="-0.0 -0.025 -0.175" rpy="0 0 0"/>
    <geometry>
      <mesh filename="package://brazo_omni_v2_description/meshes/l2_1.stl" scale="0.001 0.001 0.001"/>
    </geometry>
    <material name="silver"/>
  </visual>
  <collision>
    <origin xyz="-0.0 -0.025 -0.175" rpy="0 0 0"/>
    <geometry>
      <mesh filename="package://brazo_omni_v2_description/meshes/l2_1.stl" scale="0.001 0.001 0.001"/>
    </geometry>
  </collision>
</link>

<link name="l3_1">
  <inertial>
    <origin xyz="1.5924509514741469e-10 -0.024999988944218378 0.06944981476509277" rpy="0 0 0"/>
    <mass value="0.7212107061266956"/>
    <inertia ixx="0.00243" iyy="0.002364" izz="0.000137" ixy="-0.0" iyz="-0.0" ixz="-0.0"/>
  </inertial>
  <visual>
    <origin xyz="-0.0 -0.025 -0.325" rpy="0 0 0"/>
    <geometry>
      <mesh filename="package://brazo_omni_v2_description/meshes/l3_1.stl" scale="0.001 0.001 0.001"/>
    </geometry>
    <material name="silver"/>
  </visual>
  <collision>
    <origin xyz="-0.0 -0.025 -0.325" rpy="0 0 0"/>
    <geometry>
      <mesh filename="package://brazo_omni_v2_description/meshes/l3_1.stl" scale="0.001 0.001 0.001"/>
    </geometry>
  </collision>
</link>

<link name="eff_1_1">
  <inertial>
    <origin xyz="0.00022190767864116318 -0.024999995073830102 0.0033250062490560728" rpy="0 0 0"/>
    <mass value="0.23955016544085592"/>
    <inertia ixx="7e-05" iyy="4.8e-05" izz="4.4e-05" ixy="0.0" iyz="-0.0" ixz="-2e-06"/>
  </inertial>
  <visual>
    <origin xyz="-0.0 -0.025 -0.475" rpy="0 0 0"/>
    <geometry>
      <mesh filename="package://brazo_omni_v2_description/meshes/eff_1_1.stl" scale="0.001 0.001 0.001"/>
    </geometry>
    <material name="silver"/>
  </visual>
  <collision>
    <origin xyz="-0.0 -0.025 -0.475" rpy="0 0 0"/>
    <geometry>
      <mesh filename="package://brazo_omni_v2_description/meshes/eff_1_1.stl" scale="0.001 0.001 0.001"/>
    </geometry>
  </collision>
</link>

<link name="eff_2_1">
  <inertial>
    <origin xyz="-0.006622721772453566 -2.385833209151547e-13 0.011738496925933317" rpy="0 0 0"/>
    <mass value="0.016665776391530194"/>
    <inertia ixx="1e-06" iyy="1e-06" izz="0.0" ixy="-0.0" iyz="0.0" ixz="0.0"/>
  </inertial>
  <visual>
    <origin xyz="-0.009226 0.0 -0.525981" rpy="0 0 0"/>
    <geometry>
      <mesh filename="package://brazo_omni_v2_description/meshes/eff_2_1.stl" scale="0.001 0.001 0.001"/>
    </geometry>
    <material name="silver"/>
  </visual>
  <collision>
    <origin xyz="-0.009226 0.0 -0.525981" rpy="0 0 0"/>
    <geometry>
      <mesh filename="package://brazo_omni_v2_description/meshes/eff_2_1.stl" scale="0.001 0.001 0.001"/>
    </geometry>
  </collision>
</link>

<!-- <link name="l2_1">
  <inertial>
    <origin xyz="1.592451013345226e-10 -0.024999988944218367 0.06944981476509296" rpy="0 0 0"/>
    <mass value="0.7212107061266951"/>
    <inertia ixx="0.00243" iyy="0.002364" izz="0.000137" ixy="-0.0" iyz="-0.0" ixz="-0.0"/>
  </inertial>
  <visual>
    <origin xyz="-0.0 -0.025 -0.175" rpy="0 0 0"/>
    <geometry>
      <mesh filename="package://brazo_omni_v2_description/meshes/l2_1.stl" scale="0.001 0.001 0.001"/>
    </geometry>
    <material name="silver"/>
  </visual>
  <collision>
    <origin xyz="-0.0 -0.025 -0.175" rpy="0 0 0"/>
    <geometry>
      <mesh filename="package://brazo_omni_v2_description/meshes/l2_1.stl" scale="0.001 0.001 0.001"/>
    </geometry>
  </collision>
</link> -->

<!-- <link name="l3_1">
  <inertial>
    <origin xyz="1.5924509514741469e-10 -0.024999988944218378 0.06944981476509277" rpy="0 0 0"/>
    <mass value="0.7212107061266956"/>
    <inertia ixx="0.00243" iyy="0.002364" izz="0.000137" ixy="-0.0" iyz="-0.0" ixz="-0.0"/>
  </inertial>
  <visual>
    <origin xyz="-0.0 -0.025 -0.325" rpy="0 0 0"/>
    <geometry>
      <mesh filename="package://brazo_omni_v2_description/meshes/l3_1.stl" scale="0.001 0.001 0.001"/>
    </geometry>
    <material name="silver"/>
  </visual>
  <collision>
    <origin xyz="-0.0 -0.025 -0.325" rpy="0 0 0"/>
    <geometry>
      <mesh filename="package://brazo_omni_v2_description/meshes/l3_1.stl" scale="0.001 0.001 0.001"/>
    </geometry>
  </collision>
</link>  -->
<!-- 
<link name="eff_1_1">
  <inertial>
    <origin xyz="0.00022190767864116318 -0.024999995073830102 0.0033250062490560728" rpy="0 0 0"/>
    <mass value="0.23955016544085592"/>
    <inertia ixx="7e-05" iyy="4.8e-05" izz="4.4e-05" ixy="0.0" iyz="-0.0" ixz="-2e-06"/>
  </inertial>
  <visual>
    <origin xyz="-0.0 -0.025 -0.475" rpy="0 0 0"/>
    <geometry>
      <mesh filename="package://brazo_omni_v2_description/meshes/eff_1_1.stl" scale="0.001 0.001 0.001"/>
    </geometry>
    <material name="silver"/>
  </visual>
  <collision>
    <origin xyz="-0.0 -0.025 -0.475" rpy="0 0 0"/>
    <geometry>
      <mesh filename="package://brazo_omni_v2_description/meshes/eff_1_1.stl" scale="0.001 0.001 0.001"/>
    </geometry>
  </collision>
</link> -->

<joint name="l1_to_base_link" type="revolute">
  <origin xyz="0.0 0.025 0.025" rpy="0 0 0"/>
  <parent link="base_link"/>
  <child link="l1_1"/>
  <axis xyz="0.0 1.0 0.0"/>
  <limit upper="1.570796" lower="-1.570796" effort="100" velocity="100"/>
</joint>

<joint name="l2_to_l1" type="revolute">
  <origin xyz="0.0 0.0 0.15" rpy="0 0 0"/>
  <parent link="l1_1"/>
  <child link="l2_1"/>
  <axis xyz="0.0 1.0 0.0"/>
  <limit upper="1.919862" lower="-1.919862" effort="100" velocity="100"/>
</joint>

<joint name="l3_to_l2" type="revolute">
  <origin xyz="0.0 0.0 0.15" rpy="0 0 0"/>
  <parent link="l2_1"/>
  <child link="l3_1"/>
  <axis xyz="0.0 1.0 -0.0"/>
  <limit upper="1.919862" lower="-1.919862" effort="100" velocity="100"/>
</joint>

<joint name="end_effector_to_l3" type="revolute">
  <origin xyz="0.0 0.0 0.15" rpy="0 0 0"/>
  <parent link="l3_1"/>
  <child link="eff_1_1"/>
  <axis xyz="-0.0 1.0 -0.0"/>
  <limit upper="2.094395" lower="-2.094395" effort="100" velocity="100"/>
</joint>

<joint name="eff_2_to_eff_1" type="fixed">
  <origin xyz="0.009226 -0.025 0.050981" rpy="0 0 0"/>
  <parent link="eff_1_1"/>
  <child link="eff_2_1"/>
</joint>
<!-- 
<joint name="Revolucion 6" type="revolute">
  <origin xyz="0.0 0.0 0.15" rpy="0 0 0"/>
  <parent link="l1_1"/>
  <child link="l2_1"/>
  <axis xyz="0.0 1.0 0.0"/>
  <limit upper="1.989675" lower="-1.989675" effort="100" velocity="100"/>
</joint>

<joint name="Revolucion 7" type="revolute">
  <origin xyz="0.0 0.0 0.15" rpy="0 0 0"/>
  <parent link="l2_1"/>
  <child link="l3_1"/>
  <axis xyz="0.0 1.0 -0.0"/>
  <limit upper="1.989675" lower="-1.989675" effort="100" velocity="100"/>
</joint>

<joint name="Revolucion 8" type="revolute">
  <origin xyz="0.0 0.0 0.15" rpy="0 0 0"/>
  <parent link="l3_1"/>
  <child link="eff_1_1"/>
  <axis xyz="-0.0 1.0 -0.0"/>
  <limit upper="2.268928" lower="-2.268928" effort="100" velocity="100"/>
</joint> -->

</robot>
